# Error Handling in Julia: Working with `try-catch`

Errors are a part of programming. They can happen due to various reasons, such as:
- **Invalid user input:**  A user might enter text when a number is expected.
- **File not found:** Your program might try to open a file that doesn't exist.
- **Network issues:**  Connecting to a server might fail.
- **Logic errors in your code:**  You might have written code that attempts an invalid operation, like dividing by zero.

If you don't handle errors, your program might crash or produce incorrect results, leading to a bad user experience or even more serious problems in critical applications. Julia provides robust mechanisms for error handling, allowing you to write more resilient and reliable programs. The most fundamental tool for this is the `try-catch` block.

## Basic `try-catch` Blocks

The `try-catch` block allows you to attempt a block of code that might produce an error and then handle that error gracefully if it occurs.  Here's the basic syntax:

```julia
try
    # Code that might throw an error
    risky_operation()
catch
    # Code to execute if an error occurs in the `try` block
    handle_error()
end
```

Let's look at a simple example. Consider division by zero, which is an error in Julia:

```julia
function divide_numbers(a, b)
    try
        result = a / b
        println("The result is: ", result)
    catch
        println("Oops! Division by zero occurred.")
    end
end

divide_numbers(10, 2)
divide_numbers(5, 0)
```

In this example:
- The `try` block contains the potentially error-prone operation `a / b`.
- If `b` is zero, a `DivideError` is thrown.
- The `catch` block immediately executes when an error happens in the `try` block. In this case, it prints an error message.
- If no error occurs in the `try` block (like when `b` is 2), the `catch` block is skipped entirely.

```@output
The result is: 5.0
Oops! Division by zero occurred.
```

## Accessing Error Information

Sometimes, you need to know more about the error that occurred.  The `catch` block can optionally take a variable name after the `catch` keyword. This variable will hold the error object that was thrown.

```julia
try
    # Code that might throw an error
    risky_operation()
catch error
    # Code to execute if an error occurs, with access to the error object
    handle_error(error)
end
```

Let's modify our previous example to print the type of error:

```julia
function divide_numbers_with_error_info(a, b)
    try
        result = a / b
        println("The result is: ", result)
    catch e # 'e' will hold the error object
        println("An error of type ", typeof(e), " occurred.")
    end
end

divide_numbers_with_error_info(10, 2)
divide_numbers_with_error_info(5, 0)
```

```@output
The result is: 5.0
An error of type DivideError occurred.
```

Here, `e` in `catch e` captures the error object.  `typeof(e)` gives us the type of the error, which is `DivideError` in this case. You can then use this error object to get more details or handle different error types specifically.

## The `finally` Block

The `finally` block provides a way to execute code *regardless* of whether an error occurred in the `try` block or not. It is placed after the `catch` block (if present). Common uses for `finally` include:
- **Cleaning up resources:** Closing files, releasing network connections, or freeing memory.
- **Ensuring code runs:**  For actions that must happen no matter what.

The syntax is:

```julia
try
    # Risky code
    risky_operation()
catch error
    # Handle error (optional)
    handle_error(error)
finally
    # Code to execute no matter what
    cleanup_actions()
end
```

Let's illustrate with an example that opens and closes a file. Even if an error occurs while processing the file, we want to ensure the file is closed:

```julia
function process_file(filename)
    file_handle = nothing # Initialize outside try block for `finally` access
    try
        file_handle = open(filename, "r")
        println("File opened successfully.")
        # Simulate an error happening during processing (e.g., file might be empty)
        if filesize(filename) == 0
            error("File is empty!") # Manually throw an error
        end
        # ... process file content ...
        println("File processed.")
    catch e
        println("Error processing file: ", e)
    finally
        if file_handle !== nothing
            close(file_handle)
            println("File handle closed in finally block.")
        else
            println("File handle was never opened, no need to close in finally.")
        end
    end
end

# Create an empty file for testing
touch("empty_file.txt")
process_file("empty_file.txt")

# Create a non-empty file for testing
write("non_empty_file.txt", "Some content")
process_file("non_empty_file.txt")

rm("empty_file.txt") # Clean up files
rm("non_empty_file.txt")
```

```@output
File opened successfully.
Error processing file: ErrorException("File is empty!")
File handle closed in finally block.
File opened successfully.
File processed.
File handle closed in finally block.
```

In this example:
- `file_handle` is initialized to `nothing` outside the `try` block so that the `finally` block can access it.
- `open(filename, "r")` attempts to open the file.
- We simulate an error if the file is empty using `error("File is empty!")`. This will cause the execution to jump to the `catch` block.
- The `finally` block always runs. It checks if `file_handle` is not `nothing` (meaning the file was successfully opened) and then closes it using `close(file_handle)`.  This ensures the file is closed whether an error occurred or not.

## Nested `try-catch` Blocks

You can nest `try-catch` blocks inside each other. This can be useful for handling errors at different levels of your code or for handling specific error types differently.

```julia
try
    # Outer try block
    println("Outer try block started.")
    try
        # Inner try block - might throw an error
        println("Inner try block started.")
        error("Error from inner block!")
    catch inner_error
        # Handle error from inner block
        println("Caught inner error: ", inner_error)
        # Optionally re-throw or continue
        # rethrow(inner_error) # Example of re-throwing to outer catch
    finally
        println("Inner finally block executed.")
    end
    println("Outer try block continues after inner try-catch.") # Will reach here if inner catch handles the error
catch outer_error
    # Handle error if it propagates out of the inner try-catch (e.g., if re-thrown)
    println("Caught outer error: ", outer_error) # Would be reached if `rethrow` was used in inner catch
finally
    println("Outer finally block executed.")
end

println("Program continues after outer try-catch.")
```

```@output
Outer try block started.
Inner try block started.
Caught inner error: ErrorException("Error from inner block!")
Inner finally block executed.
Outer try block continues after inner try-catch.
Outer finally block executed.
Program continues after outer try-catch.
```

In this nested example:
- An error is deliberately thrown in the inner `try` block.
- The inner `catch` block catches and handles this error.
- Both inner and outer `finally` blocks are executed.
- Because the inner `catch` handled the error, the execution continues in the outer `try` block after the inner `try-catch`.
- If we uncomment `rethrow(inner_error)` in the inner `catch`, the error would propagate out and be caught by the *outer* `catch` block instead.

## Best Practices for Error Handling

- **Be specific:**  Catch only the errors you can actually handle.  Don't use a generic `catch` block to swallow all errors if you don't know how to respond to them.  In more advanced scenarios, you might catch specific error types (like `DivideError`, `FileNotFoundError`) and handle them differently.
- **Use `finally` for cleanup:** Always use `finally` blocks to ensure essential cleanup tasks are performed, especially when dealing with resources like files or network connections.
- **Provide informative error messages:** When handling errors, log or display helpful messages that can aid in debugging or inform the user what went wrong and how to proceed.
- **Consider logging:** For production applications, logging errors to a file or a monitoring system is crucial for tracking and resolving issues.
- **Don't overuse `try-catch`:** Error handling has a performance overhead.  Use `try-catch` only where errors are genuinely expected and need to be handled.  For simple validation or checks, conditional statements (`if`, `else`) might be more efficient.
- **Let it crash (sometimes):** For non-critical applications or in early development stages, sometimes it's better to let the program crash and show a stack trace. This can quickly point you to the source of the error, which is often preferable to masking errors and potentially leading to more subtle problems later.
